python main.py --anomaly FETCH_LARGE_DATA ended at 1734092101
